Workbook

Sheet 需求列表
A1: 编号 | B1: 需求内容 | C1: 发送时间 | D1: 返回时间 | E1: 语言 | F1: 原文字数 | G1: 单价 | H1: 费用（含税）
A2: 1 | F2: =Sheet1!J13 -> 0 | G2: 0 | H2: =F2*G2*1.06 -> 0
A3: 2 | F3: =Sheet1!J28 -> 0 | G3: 0 | H3: =F3*G3*1.06 -> 0
A4: 3 | F4: =Sheet1!J43 -> 0 | G4: 0 | H4: =F4*G4*1.06 -> 0
A5: 4 | F5: =Sheet1!J58 -> 0 | G5: 0 | H5: =F5*G5*1.06 -> 0
A6: 5 | F6: =Sheet1!J73 -> 0 | G6: 0 | H6: =F6*G6*1.06 -> 0
A7: 6 | F7: =Sheet1!J88 -> 0 | G7: 0 | H7: =F7*G7*1.06 -> 0
A8: 7 | F8: =Sheet1!J103 -> 0 | G8: 0 | H8: =F8*G8*1.06 -> 0
A9: 8 | F9: =Sheet1!J118 -> 0 | G9: 0 | H9: =F9*G9*1.06 -> 0
A10: 9 | F10: =Sheet1!J133 -> 0 | G10: 0 | H10: =F10*G10*1.06 -> 0
A11: 10 | F11: =Sheet1!J148 -> 0 | G11: 0 | H11: =F11*G11*1.06 -> 0
A12: 11 | F12: =Sheet1!J163 -> 0 | G12: 0 | H12: =F12*G12*1.06 -> 0
A13: 12 | F13: =Sheet1!J178 -> 0 | G13: 0 | H13: =F13*G13*1.06 -> 0
A14: 13 | F14: =Sheet1!J193 -> 0 | G14: 0 | H14: =F14*G14*1.06 -> 0
A15: 14 | F15: =Sheet1!J208 -> 0 | G15: 0 | H15: =F15*G15*1.06 -> 0
A16: 15 | F16: =Sheet1!J223 -> 0 | G16: 0 | H16: =F16*G16*1.06 -> 0
A17: 16 | F17: =Sheet1!J238 -> 0 | G17: 0 | H17: =F17*G17*1.06 -> 0
A18: 17 | F18: =Sheet1!J253 -> 0 | G18: 0 | H18: =F18*G18*1.06 -> 0
A19: 18 | F19: =Sheet1!J268 -> 0 | G19: 0 | H19: =F19*G19*1.06 -> 0
A20: 19 | F20: =Sheet1!J283 -> 0 | G20: 0 | H20: =F20*G20*1.06 -> 0
A21: 20 | F21: =Sheet1!J298 -> 0 | G21: 0 | H21: =F21*G21*1.06 -> 0
A22: 21 | F22: =Sheet1!J313 -> 0 | G22: 0 | H22: =F22*G22*1.06 -> 0
A23: 22 | F23: =Sheet1!J328 -> 0 | G23: 0 | H23: =F23*G23*1.06 -> 0
A24: 23 | F24: =Sheet1!J343 -> 0 | G24: 0 | H24: =F24*G24*1.06 -> 0
A25: 24 | F25: =Sheet1!J358 -> 0 | G25: 0 | H25: =F25*G25*1.06 -> 0
A26: 25 | F26: =Sheet1!J373 -> 0 | G26: 0 | H26: =F26*G26*1.06 -> 0
A27: 26 | F27: =Sheet1!J388 -> 0 | G27: 0 | H27: =F27*G27*1.06 -> 0
A28: 27 | F28: =Sheet1!J403 -> 0 | G28: 0 | H28: =F28*G28*1.06 -> 0
A29: 28 | F29: =Sheet1!J418 -> 0 | G29: 0 | H29: =F29*G29*1.06 -> 0
A30: 29 | F30: =Sheet1!J433 -> 0 | G30: 0 | H30: =F30*G30*1.06 -> 0
A31: 30 | F31: =Sheet1!J448 -> 0 | G31: 0 | H31: =F31*G31*1.06 -> 0
A32: 31 | F32: =Sheet1!J463 -> 0 | G32: 0 | H32: =F32*G32*1.06 -> 0
A33: 32 | F33: =Sheet1!J478 -> 0 | G33: 0 | H33: =F33*G33*1.06 -> 0
A34: 33 | F34: =Sheet1!J493 -> 0 | G34: 0 | H34: =F34*G34*1.06 -> 0
A35: 34 | F35: =Sheet1!J508 -> 0 | G35: 0 | H35: =F35*G35*1.06 -> 0
A36: 35 | F36: =Sheet1!J523 -> 0 | G36: 0 | H36: =F36*G36*1.06 -> 0
A37: 36 | F37: =Sheet1!J538 -> 0 | G37: 0 | H37: =F37*G37*1.06 -> 0
A38: 37 | F38: =Sheet1!J553 -> 0 | G38: 0 | H38: =F38*G38*1.06 -> 0
A39: 38 | F39: =Sheet1!J568 -> 0 | G39: 0 | H39: =F39*G39*1.06 -> 0
A40: 39 | F40: =Sheet1!J583 -> 0 | G40: 0 | H40: =F40*G40*1.06 -> 0
...

Sheet Sheet1
A1: =需求列表!B2 -> 0
A2: Type | B2: Segments | C2: Source words | D2: Source non-Asian words | E2: Source Asian characters | F2: Source chars | G2: Source tags | H2: Percent | I2: 比例 | J2: 结算 字数
A3: All | I3: 0 | J3: =E3*I3 -> 0
A4: X-translated / double context | I4: 0 | J4: =E4*I4 -> 0
A5: Repetition | I5: 0 | J5: =E5*I5 -> 0
A6: 1.01 | I6: 0 | J6: =E6*I6 -> 0
A7: 1 | I7: 0 | J7: =E7*I7 -> 0
A8: 95%-99% | I8: 0 | J8: =E8*I8 -> 0
A9: 85%-94% | I9: 1 | J9: =E9*I9 -> 0
A10: 75%-84% | I10: 1 | J10: =E10*I10 -> 0
A11: 50%-74% | I11: 1 | J11: =E11*I11 -> 0
A12: No match | I12: 1 | J12: =E12*I12 -> 0
J13: =SUM(J3:J12) -> 0
A16: =需求列表!B3 -> 0
A17: Type | B17: Segments | C17: Source words | D17: Source non-Asian words | E17: Source Asian characters | F17: Source chars | G17: Source tags | H17: Percent | I17: 比例 | J17: 结算 字数
A18: All | I18: 0 | J18: =E18*I18 -> 0
A19: X-translated / double context | I19: 0 | J19: =E19*I19 -> 0
A20: Repetition | I20: 0 | J20: =E20*I20 -> 0
A21: 1.01 | I21: 0 | J21: =E21*I21 -> 0
A22: 1 | I22: 0 | J22: =E22*I22 -> 0
A23: 95%-99% | I23: 0 | J23: =E23*I23 -> 0
A24: 85%-94% | I24: 1 | J24: =E24*I24 -> 0
A25: 75%-84% | I25: 1 | J25: =E25*I25 -> 0
A26: 50%-74% | I26: 1 | J26: =E26*I26 -> 0
A27: No match | I27: 1 | J27: =E27*I27 -> 0
J28: =SUM(J18:J27) -> 0
A31: =需求列表!B4 -> 0
A32: Type | B32: Segments | C32: Source words | D32: Source non-Asian words | E32: Source Asian characters | F32: Source chars | G32: Source tags | H32: Percent | I32: 比例 | J32: 结算 字数
A33: All | I33: 0 | J33: =E33*I33 -> 0
A34: X-translated / double context | I34: 0 | J34: =E34*I34 -> 0
A35: Repetition | I35: 0 | J35: =E35*I35 -> 0
A36: 1.01 | I36: 0 | J36: =E36*I36 -> 0
A37: 1 | I37: 0 | J37: =E37*I37 -> 0
A38: 95%-99% | I38: 0 | J38: =E38*I38 -> 0
A39: 85%-94% | I39: 1 | J39: =E39*I39 -> 0
A40: 75%-84% | I40: 1 | J40: =E40*I40 -> 0
A41: 50%-74% | I41: 1 | J41: =E41*I41 -> 0
A42: No match | I42: 1 | J42: =E42*I42 -> 0
J43: =SUM(J33:J42) -> 0
A46: =需求列表!B5 -> 0
...
