Workbook

Sheet 本地化报价
C3: 报价单
C6: 报价信息
C7: 报价单号： | E7: =TEXT(H7,"YYYYMMDD") -> 20260507 | G7: 报价日期： | H7: 46149
C9: 文件名 | F9: 原文字数 | G9: 每字单价(CNY) | H9: 金额 (CNY) | I9: 增值税 | J9: 总额 (CNY)
F10: =字数统计!J16 -> 0 | G10: 0.64 | H10: =F10*G10 -> 0 | I10: 0.06 | J10: =H10*106% -> 0
F11: =字数统计!J32 -> 0 | G11: 0.64 | H11: =F11*G11 -> 0 | I11: 0.06 | J11: =H11*106% -> 0
F12: =字数统计!J48 -> 0 | G12: 0.64 | H12: =F12*G12 -> 0 | I12: 0.06 | J12: =H12*106% -> 0
F13: =字数统计!J64 -> 0 | G13: 0.64 | H13: =F13*G13 -> 0 | I13: 0.06 | J13: =H13*106% -> 0
F14: =字数统计!J80 -> 0 | G14: 0.64 | H14: =F14*G14 -> 0 | I14: 0.06 | J14: =H14*106% -> 0
F15: =字数统计!J96 -> 0 | G15: 0.64 | H15: =F15*G15 -> 0 | I15: 0.06 | J15: =H15*106% -> 0
C17: 境外转账(CNY) | G17: 增值税普通发票/专用发票(CNY)
C18: =SUM(H10:H15) -> 0 | G18: =SUM(J10:J15) -> 0
C20: 交付日期： | F20: 46151
C21: * 本报价有效期为自报价日起1个月以内
C22: * 收费文字数计算规则 1.标点和字符不计数 2.TM交叉排重 3.高度重复内容按照以下规则计数 重复率95~100%→不额外收费 重复率0~94%→收费为正常价格的100%
C23: 联系信息
C25: 我司名称： | E25: 大连游者之家信息技术有限公司
C26: 我司地址： | E26: 辽宁省大连市高新园区黄浦路533号 海创国际大厦7层07单元
C27: 联系人员： | E27: 殷守纪
C28: 联系电话： | E28: 136-5428-7085

Sheet 字数统计
A3: 文件名：
A4: =本地化报价!C10 -> 0
A5: Type | B5: Segments | C5: Source words | D5: Source non-Asian words | E5: Source Asian characters | F5: Source chars | G5: Source tags | H5: Percent | I5: 比例 | J5: 结算 字数
A6: All | I6: 0 | J6: =E6*I6 -> 0
A7: X-translated / double context | I7: 0 | J7: =E7*I7 -> 0
A8: Repetition | I8: 0 | J8: =E8*I8 -> 0
A9: 1.01 | I9: 0 | J9: =E9*I9 -> 0
A10: 1 | I10: 0 | J10: =E10*I10 -> 0
A11: 95%-99% | I11: 0 | J11: =E11*I11 -> 0
A12: 85%-94% | I12: 1 | J12: =E12*I12 -> 0
A13: 75%-84% | I13: 1 | J13: =E13*I13 -> 0
A14: 50%-74% | I14: 1 | J14: =E14*I14 -> 0
A15: No match | I15: 1 | J15: =E15*I15 -> 0
J16: =SUM(J6:J15) -> 0
A19: 文件名：
A20: =本地化报价!C11 -> 0
A21: Type | B21: Segments | C21: Source words | D21: Source non-Asian words | E21: Source Asian characters | F21: Source chars | G21: Source tags | H21: Percent | I21: 比例 | J21: 结算 字数
A22: All | I22: 0 | J22: =E22*I22 -> 0
A23: X-translated / double context | I23: 0 | J23: =E23*I23 -> 0
A24: Repetition | I24: 0 | J24: =E24*I24 -> 0
A25: 1.01 | I25: 0 | J25: =E25*I25 -> 0
A26: 1 | I26: 0 | J26: =E26*I26 -> 0
A27: 95%-99% | I27: 0 | J27: =E27*I27 -> 0
A28: 85%-94% | I28: 1 | J28: =E28*I28 -> 0
A29: 75%-84% | I29: 1 | J29: =E29*I29 -> 0
A30: 50%-74% | I30: 1 | J30: =E30*I30 -> 0
A31: No match | I31: 1 | J31: =E31*I31 -> 0
J32: =SUM(J22:J31) -> 0
A35: 文件名：
A36: =本地化报价!C12 -> 0
A37: Type | B37: Segments | C37: Source words | D37: Source non-Asian words | E37: Source Asian characters | F37: Source chars | G37: Source tags | H37: Percent | I37: 比例 | J37: 结算 字数
A38: All | I38: 0 | J38: =E38*I38 -> 0
A39: X-translated / double context | I39: 0 | J39: =E39*I39 -> 0
A40: Repetition | I40: 0 | J40: =E40*I40 -> 0
A41: 1.01 | I41: 0 | J41: =E41*I41 -> 0
A42: 1 | I42: 0 | J42: =E42*I42 -> 0
A43: 95%-99% | I43: 0 | J43: =E43*I43 -> 0
A44: 85%-94% | I44: 1 | J44: =E44*I44 -> 0
A45: 75%-84% | I45: 1 | J45: =E45*I45 -> 0
A46: 50%-74% | I46: 1 | J46: =E46*I46 -> 0
...
