Workbook

Sheet 本地化报价
C3: 报价单(中译日)
C6: 报价信息
C7: 报价单号： | E7: =TEXT(H7,"YYYYMMDD") -> 20260410 | G7: 报价日期： | H7: 46122
C9: 服务内容 | F9: 字数 | G9: 每字单价(CNY) | H9: 金额 (CNY) | I9: 交付日
C10: =字数统计!C3 -> 0 | F10: =字数统计!D3 -> 0 | G10: 0.32 | H10: =F10*G10 -> 0 | I10: 9/17 (星期三)
C11: =字数统计!C4 -> 0 | F11: =字数统计!D4 -> 0 | G11: 0.32 | H11: =F11*G11 -> 0 | I11: 9/17 (星期三)
C12: =字数统计!C5 -> 0 | F12: =字数统计!D5 -> 0 | G12: 0.32 | H12: =F12*G12 -> 0 | I12: 9/17 (星期三)
C13: =字数统计!C6 -> 0 | F13: =字数统计!D6 -> 0 | G13: 0.32 | H13: =F13*G13 -> 0 | I13: 9/17 (星期三)
C14: =字数统计!C7 -> 0 | F14: =字数统计!D7 -> 0 | G14: 0.32 | H14: =F14*G14 -> 0 | I14: 9/17 (星期三)
C15: =字数统计!C8 -> 0 | F15: =字数统计!D8 -> 0 | G15: 0.32 | H15: =F15*G15 -> 0 | I15: 9/17 (星期三)
C16: =字数统计!C9 -> 0 | F16: =字数统计!D9 -> 0 | G16: 0.32 | H16: =F16*G16 -> 0 | I16: 9/17 (星期三)
C17: =字数统计!C10 -> 0 | F17: =字数统计!D10 -> 0 | G17: 0.32 | H17: =F17*G17 -> 0 | I17: 9/17 (星期三)
C18: =字数统计!C11 -> 0 | F18: =字数统计!D11 -> 0 | G18: 0.32 | H18: =F18*G18 -> 0 | I18: 9/17 (星期三)
C19: =字数统计!C12 -> 0 | F19: =字数统计!D12 -> 0 | G19: 0.32 | H19: =F19*G19 -> 0 | I19: 9/17 (星期三)
C20: =字数统计!C13 -> 0 | F20: =字数统计!D13 -> 0 | G20: 0.32 | H20: =F20*G20 -> 0 | I20: 9/17 (星期三)
C21: =字数统计!C14 -> 0 | F21: =字数统计!D14 -> 0 | G21: 0.32 | H21: =F21*G21 -> 0 | I21: 9/17 (星期三)
... C26: =字数统计!C19 -> 0 | F26: =字数统计!D19 -> 0 | G26: 0.32 | H26: =F26*G26 -> 0 | I26: 10/17 (星期五)
C27: =字数统计!C20 -> 0 | F27: =字数统计!D20 -> 0 | G27: 0.32 | H27: =F27*G27 -> 0
C28: =字数统计!C21 -> 0 | F28: =字数统计!D21 -> 0 | G28: 0.32 | H28: =F28*G28 -> 0
C29: =字数统计!C22 -> 0 | F29: =字数统计!D22 -> 0 | G29: 0.32 | H29: =F29*G29 -> 0 | I29: =字数统计!E22 -> 0
C30: =字数统计!C23 -> 0 | F30: =字数统计!D23 -> 0 | G30: 0.32 | H30: =F30*G30 -> 0 | I30: =字数统计!E23 -> 0
C31: =字数统计!C24 -> 0 | F31: =字数统计!D24 -> 0 | G31: 0.32 | H31: =F31*G31 -> 0 | I31: =字数统计!E24 -> 0
C32: =字数统计!C25 -> 0 | F32: =字数统计!D25 -> 0 | G32: 0.32 | H32: =F32*G32 -> 0 | I32: =字数统计!E38 -> 0
C33: =字数统计!C26 -> 0 | F33: =字数统计!D26 -> 0 | G33: 0.32 | H33: =F33*G33 -> 0 | I33: =字数统计!E39 -> 0
C34: =字数统计!C27 -> 0 | F34: =字数统计!D27 -> 0 | G34: 0.32 | H34: =F34*G34 -> 0 | I34: =字数统计!E40 -> 0
C35: =字数统计!C28 -> 0 | F35: =字数统计!D28 -> 0 | G35: 0.32 | H35: =F35*G35 -> 0 | I35: =字数统计!E41 -> 0
C36: =字数统计!C29 -> 0 | F36: =字数统计!D29 -> 0 | G36: 0.32 | H36: =F36*G36 -> 0
C37: =字数统计!C30 -> 0 | F37: =字数统计!D30 -> 0 | G37: 0.32 | H37: =F37*G37 -> 0
C38: =字数统计!C31 -> 0 | F38: =字数统计!D31 -> 0 | G38: 0.32 | H38: =F38*G38 -> 0
C39: =字数统计!C32 -> 0 | F39: =字数统计!D32 -> 0 | G39: 0.32 | H39: =F39*G39 -> 0
C40: =字数统计!C33 -> 0 | F40: =字数统计!D33 -> 0 | G40: 0.32 | H40: =F40*G40 -> 0
C41: =字数统计!C34 -> 0 | F41: =字数统计!D34 -> 0 | G41: 0.32 | H41: =F41*G41 -> 0
C42: =字数统计!C35 -> 0 | F42: =字数统计!D35 -> 0 | G42: 0.32 | H42: =F42*G42 -> 0
C43: =字数统计!C36 -> 0 | F43: =字数统计!D36 -> 0 | G43: 0.32 | H43: =F43*G43 -> 0
C44: =字数统计!C37 -> 0 | F44: =字数统计!D37 -> 0 | G44: 0.32 | H44: =F44*G44 -> 0
C45: =字数统计!C38 -> 0 | F45: =字数统计!D38 -> 0 | G45: 0.32 | H45: =F45*G45 -> 0
C46: 合计 | F46: =SUM(F10:F35) -> 0 | G46: 0.32 | H46: =F46*G46 -> 0
C48: 中译日
C49: 交付日期 | E49: 46136
C54: *本报价有效期为自报价日起1个月以内
...

Sheet 字数统计
C2: 文件名 | D2: 结算字数 | E2: 预估纳品日期 | F2: 备注 | G2: 交付状况
C3: ='字数统计2 '!A1 -> 0 | D3: ='字数统计2 '!J13 -> 0
C4: ='字数统计2 '!A21 -> 0 | D4: ='字数统计2 '!J33 -> 0
C5: ='字数统计2 '!A41 -> 0 | D5: ='字数统计2 '!J53 -> 0
C6: ='字数统计2 '!A61 -> 0 | D6: ='字数统计2 '!J73 -> 0
C7: ='字数统计2 '!A81 -> 0 | D7: ='字数统计2 '!J93 -> 0
C8: ='字数统计2 '!A101 -> 0 | D8: ='字数统计2 '!J113 -> 0
C9: ='字数统计2 '!A121 -> 0 | D9: ='字数统计2 '!J133 -> 0
C10: ='字数统计2 '!A141 -> 0 | D10: ='字数统计2 '!J153 -> 0
C11: ='字数统计2 '!A161 -> 0 | D11: ='字数统计2 '!J173 -> 0
C12: ='字数统计2 '!A181 -> 0 | D12: ='字数统计2 '!J193 -> 0
C13: ='字数统计2 '!A201 -> 0 | D13: ='字数统计2 '!J213 -> 0
C14: ='字数统计2 '!A221 -> 0 | D14: ='字数统计2 '!J233 -> 0
C15: ='字数统计2 '!A241 -> 0 | D15: ='字数统计2 '!J253 -> 0
C16: ='字数统计2 '!A261 -> 0 | D16: ='字数统计2 '!J273 -> 0
C17: ='字数统计2 '!A281 -> 0 | D17: ='字数统计2 '!J293 -> 0
C18: ='字数统计2 '!A301 -> 0 | D18: ='字数统计2 '!J313 -> 0
C19: ='字数统计2 '!A321 -> 0 | D19: ='字数统计2 '!J333 -> 0
C20: ='字数统计2 '!A341 -> 0 | D20: ='字数统计2 '!J353 -> 0
C21: ='字数统计2 '!A361 -> 0 | D21: ='字数统计2 '!J373 -> 0
C22: ='字数统计2 '!A381 -> 0 | D22: ='字数统计2 '!J393 -> 0
C23: ='字数统计2 '!A401 -> 0 | D23: ='字数统计2 '!J413 -> 0
C24: ='字数统计2 '!A421 -> 0 | D24: ='字数统计2 '!J433 -> 0
C25: ='字数统计2 '!A441 -> 0 | D25: ='字数统计2 '!J453 -> 0
C26: ='字数统计2 '!A461 -> 0 | D26: ='字数统计2 '!J473 -> 0
C27: ='字数统计2 '!A481 -> 0 | D27: ='字数统计2 '!J493 -> 0
C28: ='字数统计2 '!A501 -> 0 | D28: ='字数统计2 '!J513 -> 0
C29: ='字数统计2 '!A521 -> 0 | D29: ='字数统计2 '!J533 -> 0
C30: ='字数统计2 '!A541 -> 0 | D30: ='字数统计2 '!J553 -> 0
C31: ='字数统计2 '!A561 -> 0 | D31: ='字数统计2 '!J573 -> 0
C32: ='字数统计2 '!A581 -> 0 | D32: ='字数统计2 '!J593 -> 0
C33: ='字数统计2 '!A601 -> 0 | D33: ='字数统计2 '!J613 -> 0
C34: ='字数统计2 '!A621 -> 0 | D34: ='字数统计2 '!J633 -> 0
C35: ='字数统计2 '!A641 -> 0 | D35: ='字数统计2 '!J653 -> 0
C36: ='字数统计2 '!A661 -> 0 | D36: ='字数统计2 '!J673 -> 0
C37: ='字数统计2 '!A681 -> 0 | D37: ='字数统计2 '!J693 -> 0
C38: ='字数统计2 '!A701 -> 0 | D38: ='字数统计2 '!J713 -> 0
C39: ='字数统计2 '!A721 -> 0 | D39: ='字数统计2 '!J733 -> 0
C40: ='字数统计2 '!A741 -> 0 | D40: ='字数统计2 '!J753 -> 0
C41: 合计 | D41: =SUM(D3:D40) -> 0

Sheet 字数统计2 
A1: =重复匹配率!B22 -> 0
A2: =重复匹配率!A25 -> 0 | B2: =重复匹配率!B25 -> 0 | C2: =重复匹配率!C25 -> 0 | D2: =重复匹配率!D25 -> 0 | E2: =重复匹配率!E25 -> 0 | F2: =重复匹配率!F25 -> 0 | G2: =重复匹配率!G25 -> 0 | H2: =重复匹配率!H25 -> 0 | I2: 比例 | J2: 结算 字数
A3: =重复匹配率!A26 -> 0 | B3: =重复匹配率!B26 -> 0 | C3: =重复匹配率!C26 -> 0 | D3: =重复匹配率!D26 -> 0 | E3: =重复匹配率!E26 -> 0 | F3: =重复匹配率!F26 -> 0 | G3: =重复匹配率!G26 -> 0 | H3: =重复匹配率!H26 -> 0 | I3: 0 | J3: =E3*I3 -> 0
A4: =重复匹配率!A27 -> 0 | B4: =重复匹配率!B27 -> 0 | C4: =重复匹配率!C27 -> 0 | D4: =重复匹配率!D27 -> 0 | E4: =重复匹配率!E27 -> 0 | F4: =重复匹配率!F27 -> 0 | G4: =重复匹配率!G27 -> 0 | H4: =重复匹配率!H27 -> 0 | I4: 0 | J4: =E4*I4 -> 0
A5: =重复匹配率!A28 -> 0 | B5: =重复匹配率!B28 -> 0 | C5: =重复匹配率!C28 -> 0 | D5: =重复匹配率!D28 -> 0 | E5: =重复匹配率!E28 -> 0 | F5: =重复匹配率!F28 -> 0 | G5: =重复匹配率!G28 -> 0 | H5: =重复匹配率!H28 -> 0 | I5: 0.1 | J5: =E5*I5 -> 0
A6: =重复匹配率!A29 -> 0 | B6: =重复匹配率!B29 -> 0 | C6: =重复匹配率!C29 -> 0 | D6: =重复匹配率!D29 -> 0 | E6: =重复匹配率!E29 -> 0 | F6: =重复匹配率!F29 -> 0 | G6: =重复匹配率!G29 -> 0 | H6: =重复匹配率!H29 -> 0 | I6: 0 | J6: =E6*I6 -> 0
A7: =重复匹配率!A30 -> 0 | B7: =重复匹配率!B30 -> 0 | C7: =重复匹配率!C30 -> 0 | D7: =重复匹配率!D30 -> 0 | E7: =重复匹配率!E30 -> 0 | F7: =重复匹配率!F30 -> 0 | G7: =重复匹配率!G30 -> 0 | H7: =重复匹配率!H30 -> 0 | I7: 0.2 | J7: =E7*I7 -> 0
A8: =重复匹配率!A31 -> 0 | B8: =重复匹配率!B31 -> 0 | C8: =重复匹配率!C31 -> 0 | D8: =重复匹配率!D31 -> 0 | E8: =重复匹配率!E31 -> 0 | F8: =重复匹配率!F31 -> 0 | G8: =重复匹配率!G31 -> 0 | H8: =重复匹配率!H31 -> 0 | I8: 0.3 | J8: =E8*I8 -> 0
A9: =重复匹配率!A32 -> 0 | B9: =重复匹配率!B32 -> 0 | C9: =重复匹配率!C32 -> 0 | D9: =重复匹配率!D32 -> 0 | E9: =重复匹配率!E32 -> 0 | F9: =重复匹配率!F32 -> 0 | G9: =重复匹配率!G32 -> 0 | H9: =重复匹配率!H32 -> 0 | I9: 0.5 | J9: =E9*I9 -> 0
A10: =重复匹配率!A33 -> 0 | B10: =重复匹配率!B33 -> 0 | C10: =重复匹配率!C33 -> 0 | D10: =重复匹配率!D33 -> 0 | E10: =重复匹配率!E33 -> 0 | F10: =重复匹配率!F33 -> 0 | G10: =重复匹配率!G33 -> 0 | H10: =重复匹配率!H33 -> 0 | I10: 0.6 | J10: =E10*I10 -> 0
A11: =重复匹配率!A34 -> 0 | B11: =重复匹配率!B34 -> 0 | C11: =重复匹配率!C34 -> 0 | D11: =重复匹配率!D34 -> 0 | E11: =重复匹配率!E34 -> 0 | F11: =重复匹配率!F34 -> 0 | G11: =重复匹配率!G34 -> 0 | H11: =重复匹配率!H34 -> 0 | I11: 1 | J11: =E11*I11 -> 0
A12: =重复匹配率!A35 -> 0 | B12: =重复匹配率!B35 -> 0 | C12: =重复匹配率!C35 -> 0 | D12: =重复匹配率!D35 -> 0 | E12: =重复匹配率!E35 -> 0 | F12: =重复匹配率!F35 -> 0 | G12: =重复匹配率!G35 -> 0 | H12: =重复匹配率!H35 -> 0 | I12: 1 | J12: =E12*I12 -> 0
A13: 小计 | J13: =SUM(J3:J12) -> 0
A21: =重复匹配率!B42 -> 0
A22: =重复匹配率!A45 -> 0 | B22: =重复匹配率!B45 -> 0 | C22: =重复匹配率!C45 -> 0 | D22: =重复匹配率!D45 -> 0 | E22: =重复匹配率!E45 -> 0 | F22: =重复匹配率!F45 -> 0 | G22: =重复匹配率!G45 -> 0 | H22: =重复匹配率!H45 -> 0 | I22: 比例 | J22: 结算 字数
A23: =重复匹配率!A46 -> 0 | B23: =重复匹配率!B46 -> 0 | C23: =重复匹配率!C46 -> 0 | D23: =重复匹配率!D46 -> 0 | E23: =重复匹配率!E46 -> 0 | F23: =重复匹配率!F46 -> 0 | G23: =重复匹配率!G46 -> 0 | H23: =重复匹配率!H46 -> 0 | I23: 0 | J23: =E23*I23 -> 0
A24: =重复匹配率!A47 -> 0 | B24: =重复匹配率!B47 -> 0 | C24: =重复匹配率!C47 -> 0 | D24: =重复匹配率!D47 -> 0 | E24: =重复匹配率!E47 -> 0 | F24: =重复匹配率!F47 -> 0 | G24: =重复匹配率!G47 -> 0 | H24: =重复匹配率!H47 -> 0 | I24: 0 | J24: =E24*I24 -> 0
A25: =重复匹配率!A48 -> 0 | B25: =重复匹配率!B48 -> 0 | C25: =重复匹配率!C48 -> 0 | D25: =重复匹配率!D48 -> 0 | E25: =重复匹配率!E48 -> 0 | F25: =重复匹配率!F48 -> 0 | G25: =重复匹配率!G48 -> 0 | H25: =重复匹配率!H48 -> 0 | I25: 0.1 | J25: =E25*I25 -> 0
A26: =重复匹配率!A49 -> 0 | B26: =重复匹配率!B49 -> 0 | C26: =重复匹配率!C49 -> 0 | D26: =重复匹配率!D49 -> 0 | E26: =重复匹配率!E49 -> 0 | F26: =重复匹配率!F49 -> 0 | G26: =重复匹配率!G49 -> 0 | H26: =重复匹配率!H49 -> 0 | I26: 0 | J26: =E26*I26 -> 0
A27: =重复匹配率!A50 -> 0 | B27: =重复匹配率!B50 -> 0 | C27: =重复匹配率!C50 -> 0 | D27: =重复匹配率!D50 -> 0 | E27: =重复匹配率!E50 -> 0 | F27: =重复匹配率!F50 -> 0 | G27: =重复匹配率!G50 -> 0 | H27: =重复匹配率!H50 -> 0 | I27: 0.2 | J27: =E27*I27 -> 0
A28: =重复匹配率!A51 -> 0 | B28: =重复匹配率!B51 -> 0 | C28: =重复匹配率!C51 -> 0 | D28: =重复匹配率!D51 -> 0 | E28: =重复匹配率!E51 -> 0 | F28: =重复匹配率!F51 -> 0 | G28: =重复匹配率!G51 -> 0 | H28: =重复匹配率!H51 -> 0 | I28: 0.3 | J28: =E28*I28 -> 0
A29: =重复匹配率!A52 -> 0 | B29: =重复匹配率!B52 -> 0 | C29: =重复匹配率!C52 -> 0 | D29: =重复匹配率!D52 -> 0 | E29: =重复匹配率!E52 -> 0 | F29: =重复匹配率!F52 -> 0 | G29: =重复匹配率!G52 -> 0 | H29: =重复匹配率!H52 -> 0 | I29: 0.5 | J29: =E29*I29 -> 0
A30: =重复匹配率!A53 -> 0 | B30: =重复匹配率!B53 -> 0 | C30: =重复匹配率!C53 -> 0 | D30: =重复匹配率!D53 -> 0 | E30: =重复匹配率!E53 -> 0 | F30: =重复匹配率!F53 -> 0 | G30: =重复匹配率!G53 -> 0 | H30: =重复匹配率!H53 -> 0 | I30: 0.6 | J30: =E30*I30 -> 0
A31: =重复匹配率!A54 -> 0 | B31: =重复匹配率!B54 -> 0 | C31: =重复匹配率!C54 -> 0 | D31: =重复匹配率!D54 -> 0 | E31: =重复匹配率!E54 -> 0 | F31: =重复匹配率!F54 -> 0 | G31: =重复匹配率!G54 -> 0 | H31: =重复匹配率!H54 -> 0 | I31: 1 | J31: =E31*I31 -> 0
A32: =重复匹配率!A55 -> 0 | B32: =重复匹配率!B55 -> 0 | C32: =重复匹配率!C55 -> 0 | D32: =重复匹配率!D55 -> 0 | E32: =重复匹配率!E55 -> 0 | F32: =重复匹配率!F55 -> 0 | G32: =重复匹配率!G55 -> 0 | H32: =重复匹配率!H55 -> 0 | I32: 1 | J32: =E32*I32 -> 0
A33: 小计 | J33: =SUM(J23:J32) -> 0
A41: =重复匹配率!B62 -> 0
A42: =重复匹配率!A65 -> 0 | B42: =重复匹配率!B65 -> 0 | C42: =重复匹配率!C65 -> 0 | D42: =重复匹配率!D65 -> 0 | E42: =重复匹配率!E65 -> 0 | F42: =重复匹配率!F65 -> 0 | G42: =重复匹配率!G65 -> 0 | H42: =重复匹配率!H65 -> 0 | I42: 比例 | J42: 结算 字数
A43: =重复匹配率!A66 -> 0 | B43: =重复匹配率!B66 -> 0 | C43: =重复匹配率!C66 -> 0 | D43: =重复匹配率!D66 -> 0 | E43: =重复匹配率!E66 -> 0 | F43: =重复匹配率!F66 -> 0 | G43: =重复匹配率!G66 -> 0 | H43: =重复匹配率!H66 -> 0 | I43: 0 | J43: =E43*I43 -> 0
A44: =重复匹配率!A67 -> 0 | B44: =重复匹配率!B67 -> 0 | C44: =重复匹配率!C67 -> 0 | D44: =重复匹配率!D67 -> 0 | E44: =重复匹配率!E67 -> 0 | F44: =重复匹配率!F67 -> 0 | G44: =重复匹配率!G67 -> 0 | H44: =重复匹配率!H67 -> 0 | I44: 0 | J44: =E44*I44 -> 0
A45: =重复匹配率!A68 -> 0 | B45: =重复匹配率!B68 -> 0 | C45: =重复匹配率!C68 -> 0 | D45: =重复匹配率!D68 -> 0 | E45: =重复匹配率!E68 -> 0 | F45: =重复匹配率!F68 -> 0 | G45: =重复匹配率!G68 -> 0 | H45: =重复匹配率!H68 -> 0 | I45: 0.1 | J45: =E45*I45 -> 0
A46: =重复匹配率!A69 -> 0 | B46: =重复匹配率!B69 -> 0 | C46: =重复匹配率!C69 -> 0 | D46: =重复匹配率!D69 -> 0 | E46: =重复匹配率!E69 -> 0 | F46: =重复匹配率!F69 -> 0 | G46: =重复匹配率!G69 -> 0 | H46: =重复匹配率!H69 -> 0 | I46: 0 | J46: =E46*I46 -> 0
A47: =重复匹配率!A70 -> 0 | B47: =重复匹配率!B70 -> 0 | C47: =重复匹配率!C70 -> 0 | D47: =重复匹配率!D70 -> 0 | E47: =重复匹配率!E70 -> 0 | F47: =重复匹配率!F70 -> 0 | G47: =重复匹配率!G70 -> 0 | H47: =重复匹配率!H70 -> 0 | I47: 0.2 | J47: =E47*I47 -> 0
A48: =重复匹配率!A71 -> 0 | B48: =重复匹配率!B71 -> 0 | C48: =重复匹配率!C71 -> 0 | D48: =重复匹配率!D71 -> 0 | E48: =重复匹配率!E71 -> 0 | F48: =重复匹配率!F71 -> 0 | G48: =重复匹配率!G71 -> 0 | H48: =重复匹配率!H71 -> 0 | I48: 0.3 | J48: =E48*I48 -> 0
A49: =重复匹配率!A72 -> 0 | B49: =重复匹配率!B72 -> 0 | C49: =重复匹配率!C72 -> 0 | D49: =重复匹配率!D72 -> 0 | E49: =重复匹配率!E72 -> 0 | F49: =重复匹配率!F72 -> 0 | G49: =重复匹配率!G72 -> 0 | H49: =重复匹配率!H72 -> 0 | I49: 0.5 | J49: =E49*I49 -> 0
A50: =重复匹配率!A73 -> 0 | B50: =重复匹配率!B73 -> 0 | C50: =重复匹配率!C73 -> 0 | D50: =重复匹配率!D73 -> 0 | E50: =重复匹配率!E73 -> 0 | F50: =重复匹配率!F73 -> 0 | G50: =重复匹配率!G73 -> 0 | H50: =重复匹配率!H73 -> 0 | I50: 0.6 | J50: =E50*I50 -> 0
A51: =重复匹配率!A74 -> 0 | B51: =重复匹配率!B74 -> 0 | C51: =重复匹配率!C74 -> 0 | D51: =重复匹配率!D74 -> 0 | E51: =重复匹配率!E74 -> 0 | F51: =重复匹配率!F74 -> 0 | G51: =重复匹配率!G74 -> 0 | H51: =重复匹配率!H74 -> 0 | I51: 1 | J51: =E51*I51 -> 0
A52: =重复匹配率!A75 -> 0 | B52: =重复匹配率!B75 -> 0 | C52: =重复匹配率!C75 -> 0 | D52: =重复匹配率!D75 -> 0 | E52: =重复匹配率!E75 -> 0 | F52: =重复匹配率!F75 -> 0 | G52: =重复匹配率!G75 -> 0 | H52: =重复匹配率!H75 -> 0 | I52: 1 | J52: =E52*I52 -> 0
A53: 小计 | J53: =SUM(J43:J52) -> 0
A61: =重复匹配率!B82 -> 0
...

Sheet 重复匹配率
